<?xml version="1.0"?>
<robot name="quadrotor">
  <link name="base_link">
    <visual>
      <origin xyz="0 0 0" rpy="0.0 0.0 1.57079"/>
      <geometry>
        <mesh scale="0.001 0.001 0.001" filename="package://my_robot_description/meshes/core_battery_transformed.stl"/>
      </geometry>
      <material name="White">
        <color rgba="1 1 1 1.0"/>
      </material>
    </visual>
    <collision>
      <origin xyz="0 0 0"/>
      <geometry>
        <sphere radius="0.18384776310850237"/>
      </geometry>
    </collision>
    <inertial>
      <mass value="0.225"/>
      <inertia ixx="0.00042249999999999997" ixy="0.0" ixz="0.0" iyx="0.0" iyy="0.00042249999999999997" iyz="0.0" izx="0.0" izy="0.0" izz="0.0008449999999999999"/>
    </inertial>
  </link>

  <!-- ========== BRACCIO 0 ========== -->
  <link name="connecting_link_arm0_z"/>
  <link name="connecting_link_arm0_y"/>
  <link name="connecting_link_arm0"/>

  <!-- Rotazione Z -->
  <joint name="base_link_to_connecting_link_0_z" type="revolute" dont_collapse="false">
    <parent link="base_link"/>
    <child link="connecting_link_arm0_z"/>
    <origin xyz="0.04 -0.032 0.0" rpy="0.0 0.0 -0.78539816339"/>
    <axis xyz="0 0 1"/>
    <limit lower="-1.57" upper="1.57" effort="20" velocity="10"/>
  </joint>

  <!-- Rotazione Y -->
  <joint name="base_link_to_connecting_link_0_y" type="revolute" dont_collapse="false">
    <parent link="connecting_link_arm0_z"/>
    <child link="connecting_link_arm0_y"/>
    <origin xyz="0 0 0" rpy="0.0 0.0 0.0"/>
    <axis xyz="0 1 0"/>
    <limit lower="-0.25" upper="0.25" effort="20" velocity="10"/>
  </joint>

  <!-- Rotazione X -->
  <joint name="base_link_to_connecting_link_0_x" type="revolute" dont_collapse="false">
    <parent link="connecting_link_arm0_y"/>
    <child link="connecting_link_arm0"/>
    <origin xyz="0 0 0" rpy="0.0 0.0 0.0"/>
    <axis xyz="1 0 0"/>
    <limit lower="-0.25" upper="0.25" effort="20" velocity="10"/>
  </joint>

  <link name="arm_motor_0">
    <visual>
      <origin xyz="0 0.0 0.0" rpy="0 0 0"/>
      <geometry>
        <mesh scale="0.001 0.001 0.001" filename="package://my_robot_description/meshes/arm_transformed.stl"/>
      </geometry>
      <material name="Orange">
        <color rgba="1 0.423 0.03921568627 1.0"/>
      </material>
    </visual>
    <inertial>
      <origin xyz="0 0 0.05" rpy="0 0 0"/>
      <mass value="0.0"/>
      <inertia ixx="0.0" ixy="0.0" ixz="0.0" iyx="0.0" iyy="0.0" iyz="0.0" izx="0.0" izy="0.0" izz="0.0"/>
    </inertial>
  </link>

  <joint name="connecting_link_to_arm_motor_0" type="revolute" dont_collapse="false">
    <parent link="connecting_link_arm0"/>
    <child link="arm_motor_0"/>
    <origin xyz="0 0 0" rpy="0.0 1.57079632679 0.0"/>
    <axis xyz="1 0 0"/>
    <limit lower="-0.1" upper="0.1" effort="20.0" velocity="10.0"/>
  </joint>

  <link name="motor_0">
    <inertial>
      <mass value="0.016249999999999999"/>
      <inertia ixx="0.0" ixy="0.0" ixz="0.0" iyx="0.0" iyy="0.0" iyz="0.0" izx="0.0" izy="0.0" izz="0.0"/>
    </inertial>
  </link>

  <joint name="arm_to_motor_0" type="fixed" dont_collapse="false">
    <parent link="arm_motor_0"/>
    <child link="motor_0"/>
    <origin xyz="0 0 0.07" rpy="0.0 -1.57079632679 0.0"/>
  </joint>

  <!-- ========== BRACCIO 1 ========== -->
  <link name="connecting_link_arm1_z"/>
  <link name="connecting_link_arm1_y"/>
  <link name="connecting_link_arm1"/>

  <!-- Rotazione Z -->
  <joint name="base_link_to_connecting_link_1_z" type="revolute" dont_collapse="false">
    <parent link="base_link"/>
    <child link="connecting_link_arm1_z"/>
    <origin xyz="-0.04 -0.032 0" rpy="0.0 0.0 -2.35619449019"/>
    <axis xyz="0 0 1"/>
    <limit lower="-1.57" upper="1.57" effort="20.0" velocity="10.0"/>
  </joint>

  <!-- Rotazione Y -->
  <joint name="base_link_to_connecting_link_1_y" type="revolute" dont_collapse="false">
    <parent link="connecting_link_arm1_z"/>
    <child link="connecting_link_arm1_y"/>
    <origin xyz="0 0 0" rpy="0.0 0.0 0.0"/>
    <axis xyz="0 1 0"/>
    <limit lower="-0.25" upper="0.25" effort="20.0" velocity="10.0"/>
  </joint>

  <!-- Rotazione X -->
  <joint name="base_link_to_connecting_link_1_x" type="revolute" dont_collapse="false">
    <parent link="connecting_link_arm1_y"/>
    <child link="connecting_link_arm1"/>
    <origin xyz="0 0 0" rpy="0.0 0.0 0.0"/>
    <axis xyz="1 0 0"/>
    <limit lower="-0.25" upper="0.25" effort="20.0" velocity="10.0"/>
  </joint>

  <link name="arm_motor_1">
    <visual>
      <origin xyz="0 0.0 0.0" rpy="0 0 0"/>
      <geometry>
        <mesh scale="0.001 0.001 0.001" filename="package://my_robot_description/meshes/arm_transformed.stl"/>
      </geometry>
      <material name="Orange">
        <color rgba="1 0.423 0.03921568627 1.0"/>
      </material>
    </visual>
    <inertial>
      <origin xyz="0 0 0.09192388155" rpy="0 0 0"/>
      <mass value="0.0"/>
      <inertia ixx="0.0" ixy="0.0" ixz="0.0" iyx="0.0" iyy="0.0" iyz="0.0" izx="0.0" izy="0.0" izz="0.0"/>
    </inertial>
  </link>

  <joint name="connecting_link_to_arm_motor_1" type="revolute" dont_collapse="false">
    <parent link="connecting_link_arm1"/>
    <child link="arm_motor_1"/>
    <origin xyz="0 0 0" rpy="0.0 1.57079632679 0.0"/>
    <axis xyz="1 0 0"/>
    <limit lower="-0.1" upper="0.1" effort="20.0" velocity="10.0"/>
  </joint>

  <link name="motor_1">
    <inertial>
      <mass value="0.016249999999999999"/>
      <inertia ixx="0.0" ixy="0.0" ixz="0.0" iyx="0.0" iyy="0.0" iyz="0.0" izx="0.0" izy="0.0" izz="0.0"/>
    </inertial>
  </link>

  <joint name="arm_to_motor_1" type="fixed" dont_collapse="false">
    <parent link="arm_motor_1"/>
    <child link="motor_1"/>
    <origin xyz="0 0 0.07" rpy="0.0 -1.57079632679 0.0"/>
  </joint>

  <!-- ========== BRACCIO 2 ========== -->
  <link name="connecting_link_arm2_z"/>
  <link name="connecting_link_arm2_y"/>
  <link name="connecting_link_arm2"/>

  <!-- Rotazione Z -->
  <joint name="base_link_to_connecting_link_2_z" type="revolute" dont_collapse="false">
    <parent link="base_link"/>
    <child link="connecting_link_arm2_z"/>
    <origin xyz="-0.04 0.032 0" rpy="0.0 0.0 2.3561944901923453"/>
    <axis xyz="0 0 1"/>
    <limit lower="-1.57" upper="1.57" effort="20.0" velocity="10.0"/>
  </joint>

  <!-- Rotazione Y -->
  <joint name="base_link_to_connecting_link_2_y" type="revolute" dont_collapse="false">
    <parent link="connecting_link_arm2_z"/>
    <child link="connecting_link_arm2_y"/>
    <origin xyz="0 0 0" rpy="0.0 0.0 0.0"/>
    <axis xyz="0 1 0"/>
    <limit lower="-0.25" upper="0.25" effort="20.0" velocity="10.0"/>
  </joint>

  <!-- Rotazione X -->
  <joint name="base_link_to_connecting_link_2_x" type="revolute" dont_collapse="false">
    <parent link="connecting_link_arm2_y"/>
    <child link="connecting_link_arm2"/>
    <origin xyz="0 0 0" rpy="0.0 0.0 0.0"/>
    <axis xyz="1 0 0"/>
    <limit lower="-0.25" upper="0.25" effort="20.0" velocity="10.0"/>
  </joint>

  <link name="arm_motor_2">
    <visual>
      <origin xyz="0 0.0 0.0" rpy="0 0 0"/>
      <geometry>
        <mesh scale="0.001 0.001 0.001" filename="package://my_robot_description/meshes/arm_transformed.stl"/>
      </geometry>
      <material name="Orange">
        <color rgba="1 0.423 0.03921568627 1.0"/>
      </material>
    </visual>
    <inertial>
      <origin xyz="0 0 0.09192388155" rpy="0 0 0"/>
      <mass value="0.0"/>
      <inertia ixx="0.0" ixy="0.0" ixz="0.0" iyx="0.0" iyy="0.0" iyz="0.0" izx="0.0" izy="0.0" izz="0.0"/>
    </inertial>
  </link>

  <joint name="connecting_link_to_arm_motor_2" type="revolute" dont_collapse="false">
    <parent link="connecting_link_arm2"/>
    <child link="arm_motor_2"/>
    <origin xyz="0 0 0" rpy="0.0 1.57079632679 0.0"/>
    <axis xyz="1 0 0"/>
    <limit lower="-0.1" upper="0.1" effort="20.0" velocity="10.0"/>
  </joint>

  <link name="motor_2">
    <inertial>
      <mass value="0.016249999999999999"/>
      <inertia ixx="0.0" ixy="0.0" ixz="0.0" iyx="0.0" iyy="0.0" iyz="0.0" izx="0.0" izy="0.0" izz="0.0"/>
    </inertial>
  </link>

  <joint name="arm_to_motor_2" type="fixed" dont_collapse="false">
    <parent link="arm_motor_2"/>
    <child link="motor_2"/>
    <origin xyz="0 0 0.07" rpy="0.0 -1.57079632679 0.0"/>
  </joint>

  <!-- ========== BRACCIO 3 ========== -->
  <link name="connecting_link_arm3_z"/>
  <link name="connecting_link_arm3_y"/>
  <link name="connecting_link_arm3"/>

  <!-- Rotazione Z -->
  <joint name="base_link_to_connecting_link_3_z" type="revolute" dont_collapse="false">
    <parent link="base_link"/>
    <child link="connecting_link_arm3_z"/>
    <origin xyz="0.04 0.032 0" rpy="0.0 0.0 0.7853981633974482"/>
    <axis xyz="0 0 1"/>
    <limit lower="-1.57" upper="1.57" effort="20.0" velocity="10.0"/>
  </joint>

  <!-- Rotazione Y -->
  <joint name="base_link_to_connecting_link_3_y" type="revolute" dont_collapse="false">
    <parent link="connecting_link_arm3_z"/>
    <child link="connecting_link_arm3_y"/>
    <origin xyz="0 0 0" rpy="0.0 0.0 0.0"/>
    <axis xyz="0 1 0"/>
    <limit lower="-0.25" upper="0.25" effort="20.0" velocity="10.0"/>
  </joint>

  <!-- Rotazione X -->
  <joint name="base_link_to_connecting_link_3_x" type="revolute" dont_collapse="false">
    <parent link="connecting_link_arm3_y"/>
    <child link="connecting_link_arm3"/>
    <origin xyz="0 0 0" rpy="0.0 0.0 0.0"/>
    <axis xyz="1 0 0"/>
    <limit lower="-0.25" upper="0.25" effort="20.0" velocity="10.0"/>
  </joint>

  <link name="arm_motor_3">
    <visual>
      <origin xyz="0 0.0 0.0" rpy="0 0 0"/>
      <geometry>
        <mesh scale="0.001 0.001 0.001" filename="package://my_robot_description/meshes/arm_transformed.stl"/>
      </geometry>
      <material name="Orange">
        <color rgba="1 0.423 0.03921568627 1.0"/>
      </material>
    </visual>
    <inertial>
      <origin xyz="0 0 0.09192388155" rpy="0 0 0"/>
      <mass value="0.0"/>
      <inertia ixx="0.0" ixy="0.0" ixz="0.0" iyx="0.0" iyy="0.0" iyz="0.0" izx="0.0" izy="0.0" izz="0.0"/>
    </inertial>
  </link>

  <joint name="connecting_link_to_arm_motor_3" type="revolute" dont_collapse="false">
    <parent link="connecting_link_arm3"/>
    <child link="arm_motor_3"/>
    <origin xyz="0 0 0" rpy="0.0 1.57079632679 0.0"/>
    <axis xyz="1 0 0"/>
    <limit lower="-0.1" upper="0.1" effort="20.0" velocity="10.0"/>
  </joint>

  <link name="motor_3">
    <inertial>
      <mass value="0.016249999999999999"/>
      <inertia ixx="0.0" ixy="0.0" ixz="0.0" iyx="0.0" iyy="0.0" iyz="0.0" izx="0.0" izy="0.0" izz="0.0"/>
    </inertial>
  </link>

  <joint name="arm_to_motor_3" type="fixed" dont_collapse="false">
    <parent link="arm_motor_3"/>
    <child link="motor_3"/>
    <origin xyz="0 0 0.07" rpy="0.0 -1.57079632679 0.0"/>
  </joint>
</robot>